
<?xml version="1.0"?>
<robot name="agv_robot" xmlns:xacro="http://www.ros.org/wiki/xacro">
  
  <!-- ==================== 参数定义 ==================== -->
  <xacro:arg name="robot_id" default="0"/>
  <xacro:property name="robot_id" value="$(arg robot_id)"/>
  
  <xacro:property name="wheel_radius" value="0.075"/>
  <xacro:property name="wheel_width" value="0.04"/>
  <xacro:property name="base_width" value="0.3"/>
  <xacro:property name="base_length" value="0.4"/>
  <xacro:property name="base_height" value="0.15"/>
  
  <!-- ==================== 底盘 base_link ==================== -->
  <link name="base_link">
    <visual>
      <geometry>
        <box size="${base_length} ${base_width} ${base_height}"/>
      </geometry>
      <material name="blue">
        <color rgba="0.2 0.4 0.8 1"/>
      </material>
    </visual>
    
    <collision>
      <geometry>
        <box size="${base_length} ${base_width} ${base_height}"/>
      </geometry>
    </collision>
    
    <inertial>
      <mass value="15.0"/>
      <inertia ixx="0.3" ixy="0" ixz="0" iyy="0.4" iyz="0" izz="0.5"/>
    </inertial>
  </link>
  
  <!-- ==================== 左轮 ==================== -->
  <link name="left_wheel">
    <visual>
      <origin xyz="0 0 0" rpy="1.5707 0 0"/>
      <geometry>
        <cylinder radius="${wheel_radius}" length="${wheel_width}"/>
      </geometry>
      <material name="black">
        <color rgba="0.2 0.2 0.2 1"/>
      </material>
    </visual>
    
    <collision>
      <origin xyz="0 0 0" rpy="1.5707 0 0"/>
      <geometry>
        <cylinder radius="${wheel_radius}" length="${wheel_width}"/>
      </geometry>
    </collision>
    
    <inertial>
      <mass value="1.0"/>
      <inertia ixx="0.01" ixy="0" ixz="0" iyy="0.01" iyz="0" izz="0.01"/>
    </inertial>
  </link>
  
  <joint name="left_wheel_joint" type="continuous">
    <parent link="base_link"/>
    <child link="left_wheel"/>
    <origin xyz="0 ${base_width/2 + wheel_width/2} 0" rpy="0 0 0"/>
    <axis xyz="0 1 0"/>
  </joint>
  
  <!-- ==================== 右轮 ==================== -->
  <link name="right_wheel">
    <visual>
      <origin xyz="0 0 0" rpy="1.5707 0 0"/>
      <geometry>
        <cylinder radius="${wheel_radius}" length="${wheel_width}"/>
      </geometry>
      <material name="black">
        <color rgba="0.2 0.2 0.2 1"/>
      </material>
    </visual>
    
    <collision>
      <origin xyz="0 0 0" rpy="1.5707 0 0"/>
      <geometry>
        <cylinder radius="${wheel_radius}" length="${wheel_width}"/>
      </geometry>
    </collision>
    
    <inertial>
      <mass value="1.0"/>
      <inertia ixx="0.01" ixy="0" ixz="0" iyy="0.01" iyz="0" izz="0.01"/>
    </inertial>
  </link>
  
  <joint name="right_wheel_joint" type="continuous">
    <parent link="base_link"/>
    <child link="right_wheel"/>
    <origin xyz="0 ${-(base_width/2 + wheel_width/2)} 0" rpy="0 0 0"/>
    <axis xyz="0 1 0"/>
  </joint>
  
  <!-- ==================== 激光雷达 ==================== -->
  <link name="laser">
    <visual>
      <geometry>
        <cylinder radius="0.04" length="0.05"/>
      </geometry>
      <material name="red">
        <color rgba="0.8 0.2 0.2 1"/>
      </material>
    </visual>
    
    <collision>
      <geometry>
        <cylinder radius="0.04" length="0.05"/>
      </geometry>
    </collision>
    
    <inertial>
      <mass value="0.2"/>
      <inertia ixx="0.001" ixy="0" ixz="0" iyy="0.001" iyz="0" izz="0.001"/>
    </inertial>
  </link>
  
  <joint name="laser_joint" type="fixed">
    <parent link="base_link"/>
    <child link="laser"/>
    <origin xyz="${base_length/2 - 0.05} 0 ${base_height/2 + 0.05}" rpy="0 0 0"/>
  </joint>
  
  <!-- ==================== Gazebo插件配置 ==================== -->
  
  <!-- 差速驱动控制器 -->
  <gazebo>
    <plugin name="differential_drive_controller" filename="libgazebo_ros_diff_drive.so">
      <rosDebugLevel>Debug</rosDebugLevel>
      <publishWheelTF>false</publishWheelTF>
      <robotNamespace>/robot_${robot_id}</robotNamespace>
      <publishTf>1</publishTf>
      <publishWheelJointState>true</publishWheelJointState>
      <alwaysOn>true</alwaysOn>
      <updateRate>100.0</updateRate>
      <leftJoint>left_wheel_joint</leftJoint>
      <rightJoint>right_wheel_joint</rightJoint>
      <wheelSeparation>${base_width + wheel_width}</wheelSeparation>
      <wheelDiameter>${2*wheel_radius}</wheelDiameter>
      <broadcastTF>1</broadcastTF>
      <wheelTorque>30</wheelTorque>
      <wheelAcceleration>1.8</wheelAcceleration>
      <commandTopic>cmd_vel</commandTopic>
      <odometryFrame>odom</odometryFrame>
      <odometryTopic>odom</odometryTopic>
      <robotBaseFrame>base_link</robotBaseFrame>
      <publishOdomTF>true</publishOdomTF>
      <odometrySource>world</odometrySource>
    </plugin>
  </gazebo>
  
  <!-- 激光雷达传感器 -->
  <gazebo reference="laser">
    <material>Gazebo/Red</material>
    <sensor type="ray" name="laser_sensor">
      <pose>0 0 0 0 0 0</pose>
      <visualize>true</visualize>
      <update_rate>10</update_rate>
      <ray>
        <scan>
          <horizontal>
            <samples>360</samples>
            <resolution>1</resolution>
            <min_angle>-3.14159</min_angle>
            <max_angle>3.14159</max_angle>
          </horizontal>
        </scan>
        <range>
          <min>0.15</min>
          <max>8.0</max>
          <resolution>0.01</resolution>
        </range>
        <noise>
          <type>gaussian</type>
          <mean>0.0</mean>
          <stddev>0.01</stddev>
        </noise>
      </ray>
      <plugin name="gazebo_ros_laser" filename="libgazebo_ros_laser.so">
        <topicName>/robot_${robot_id}/scan</topicName>
        <frameName>laser</frameName>
      </plugin>
    </sensor>
  </gazebo>
  
  <!-- 物理属性 -->
  <gazebo reference="base_link">
    <material>Gazebo/Blue</material>
  </gazebo>
  
  <gazebo reference="left_wheel">
    <mu1>1.0</mu1>
    <mu2>1.0</mu2>
    <kp>1000000.0</kp>
    <kd>100.0</kd>
    <material>Gazebo/Black</material>
  </gazebo>
  
  <gazebo reference="right_wheel">
    <mu1>1.0</mu1>
    <mu2>1.0</mu2>
    <kp>1000000.0</kp>
    <kd>100.0</kd>
    <material>Gazebo/Black</material>
  </gazebo>
  
</robot>
